Workbook

Sheet Dashboard
B2: PLAN FINANCIERO - PAREJA MÉDICOS RESIDENTES
B3: Uruguay · Pediatría & Oncología Radioterápica
B5: Resumen Mensual
B6: Ingreso Neto - Pediatría | C6: =Ingresos!D21
B7: Ingreso Neto - Oncología RT | C7: =Ingresos!E21
B8: Total Ingresos Pareja | C8: =Ingresos!F21
B9: Total Gastos Mensuales | C9: =Gastos!H51
B10: Disponible para Ahorro | C10: =C8-C9
B11: Tasa de Ahorro | C11: =IF(C8>0,C10/C8,0)
B14: Progreso de Objetivos
B15: Objetivo | C15: Meta ($) | D15: Ahorrado ($) | E15: Progreso | F15: Plazo
B16: Vacaciones Juntos | C16: =Objetivos!D6 | D16: =Objetivos!E6 | E16: =IF(C16>0,D16/C16,0) | F16: corto
B17: Ahorro Individual - Ella | C17: =Objetivos!D7 | D17: =Objetivos!E7 | E17: =IF(C17>0,D17/C17,0) | F17: corto-largo
B18: Ahorro Individual - Él | C18: =Objetivos!D8 | D18: =Objetivos!E8 | E18: =IF(C18>0,D18/C18,0) | F18: corto-largo
B19: Compra Inmueble | C19: =Objetivos!D9 | D19: =Objetivos!E9 | E19: =IF(C19>0,D19/C19,0) | F19: mediano
B20: Retiro / Inversiones | C20: =Objetivos!D10 | D20: =Objetivos!E10 | E20: =IF(C20>0,D20/C20,0) | F20: largo
B23: Distribución Sugerida del Ahorro
B24: Categoría | C24: % Sugerido | D24: Monto Mensual
B25: Fondo de Emergencia (3-6 meses gastos) | C25: 0.2 | D25: =C25*Dashboard!C10
B26: Vacaciones | C26: 0.1 | D26: =C26*Dashboard!C10
B27: Ahorro Individual (c/u) | C27: 0.15 | D27: =C27*Dashboard!C10
B28: Inmueble | C28: 0.3 | D28: =C28*Dashboard!C10
B29: Retiro / Inversiones | C29: 0.25 | D29: =C29*Dashboard!C10
B32: Notas
B33: • Los montos están en pesos uruguayos (UYU). Ajustar si usan USD.
B34: • Completar primero las hojas Ingresos y Gastos.
B35: • Los objetivos se configuran en la hoja Objetivos.
B36: • El seguimiento mensual se hace en la hoja Seguimiento.
B37: • Adaptar los % de distribución a su realidad.

Sheet Ingresos
B2: INGRESOS MENSUALES
B4: Concepto | D4: Pediatría (Ella) | E4: Oncología RT (Él) | F4: Total
B5: Salario Base Residencia | F5: =D5+E5
B6: Guardias / Horas Extra | F6: =D6+E6
B7: Otros Ingresos (docencia, etc.) | F7: =D7+E7
B8: Aguinaldo (prorrateo mensual) | F8: =D8+E8
B9: Ingresos Extras | F9: =D9+E9
B10: TOTAL INGRESOS BRUTOS | D10: =SUM(D5:D9) | E10: =SUM(E5:E9) | F10: =D10+E10
B12: Deducciones
B13: Concepto | D13: Pediatría (Ella) | E13: Oncología RT (Él) | F13: Total
B14: BPS (Aporte jubilatorio) | F14: =D14+E14
B15: FONASA (Salud) | F15: =D15+E15
B16: IRPF | F16: =D16+E16
B17: Fondo de Solidaridad | F17: =D17+E17
B18: Otras deducciones | F18: =D18+E18
B19: TOTAL DEDUCCIONES | D19: =SUM(D14:D18) | E19: =SUM(E14:E18) | F19: =D19+E19
B21: INGRESO NETO MENSUAL | D21: =D10-D19 | E21: =E10-E19 | F21: =D21+E21

Sheet Gastos
B2: GASTOS MENSUALES DETALLADOS
B4: Categoría / Concepto | D4: Ella | E4: Él | F4: Compartido | H4: Total
B5: VIVIENDA
B6: Alquiler | H6: =D6+E6+F6
B7: Gastos comunes / Expensas | H7: =D7+E7+F7
B8: Electricidad (UTE) | H8: =D8+E8+F8
B9: Agua (OSE) | H9: =D9+E9+F9
B10: Internet / Cable | H10: =D10+E10+F10
B11: Gas | H11: =D11+E11+F11
B12: Seguro hogar | H12: =D12+E12+F12
B13: Subtotal Vivienda | D13: =SUM(D6:D12) | E13: =SUM(E6:E12) | F13: =SUM(F6:F12) | H13: =SUM(H6:H12)
B14: ALIMENTACIÓN
B15: Supermercado / Almacén | H15: =D15+E15+F15
B16: Feria / Verdulería | H16: =D16+E16+F16
B17: Delivery / Comer afuera | H17: =D17+E17+F17
B18: Agua / Bebidas | H18: =D18+E18+F18
B19: Subtotal Alimentación | D19: =SUM(D15:D18) | E19: =SUM(E15:E18) | F19: =SUM(F15:F18) | H19: =SUM(H15:H18)
B20: TRANSPORTE
B21: Combustible | H21: =D21+E21+F21
B22: Estacionamiento | H22: =D22+E22+F22
B23: Boleto / STM | H23: =D23+E23+F23
B24: Mantenimiento vehículo | H24: =D24+E24+F24
B25: Seguro vehículo | H25: =D25+E25+F25
B26: Subtotal Transporte | D26: =SUM(D21:D25) | E26: =SUM(E21:E25) | F26: =SUM(F21:F25) | H26: =SUM(H21:H25)
B27: SALUD
B28: Mutualista / Emergencia médica | H28: =D28+E28+F28
B29: Medicamentos | H29: =D29+E29+F29
B30: Odontología | H30: =D30+E30+F30
B31: Gimnasio / Deporte | H31: =D31+E31+F31
B32: Subtotal Salud | D32: =SUM(D28:D31) | E32: =SUM(E28:E31) | F32: =SUM(F28:F31) | H32: =SUM(H28:H31)
B33: EDUCACIÓN Y FORMACIÓN
B34: Cursos / Congresos | H34: =D34+E34+F34
B35: Libros / Material | H35: =D35+E35+F35
B36: Cuotas postgrado | H36: =D36+E36+F36
B37: Subtotal Educación Y Formación | D37: =SUM(D34:D36) | E37: =SUM(E34:E36) | F37: =SUM(F34:F36) | H37: =SUM(H34:H36)
B38: PERSONAL Y OCIO
B39: Ropa | H39: =D39+E39+F39
B40: Higiene / Cuidado personal | H40: =D40+E40+F40
B41: Entretenimiento / Salidas | H41: =D41+E41+F41
B42: Suscripciones (Netflix, Spotify, etc.) | H42: =D42+E42+F42
...

Sheet Objetivos
B2: OBJETIVOS DE AHORRO E INVERSIÓN
B3: Definir metas claras con plazos y montos específicos
B5: Objetivo | C5: Plazo | D5: Meta Total ($) | E5: Ahorrado ($) | F5: Restante ($) | G5: Ahorro Mensual Req. | H5: Fecha Inicio | I5: Fecha Meta
B6: 1. Vacaciones Juntos | C6: Corto (6-12 meses) | F6: =D6-E6 | G6: =IF(AND(H6<>"",I6<>""),F6/MAX((I6-H6)/30,1),0)
B7: 2. Ahorro Individual - Ella | C7: Corto-Largo | F7: =D7-E7 | G7: =IF(AND(H7<>"",I7<>""),F7/MAX((I7-H7)/30,1),0)
B8: 3. Ahorro Individual - Él | C8: Corto-Largo | F8: =D8-E8 | G8: =IF(AND(H8<>"",I8<>""),F8/MAX((I8-H8)/30,1),0)
B9: 4. Compra de Inmueble | C9: Mediano (3-5 años) | F9: =D9-E9 | G9: =IF(AND(H9<>"",I9<>""),F9/MAX((I9-H9)/30,1),0)
B10: 5. Retiro / Inversiones | C10: Largo (10+ años) | F10: =D10-E10 | G10: =IF(AND(H10<>"",I10<>""),F10/MAX((I10-H10)/30,1),0)
B13: Objetivo 1: Vacaciones Juntos (Corto Plazo)
B14: Destino
B15: Duración (días)
B16: Presupuesto vuelos/transporte
B17: Presupuesto alojamiento
B18: Presupuesto comida/actividades
B19: Presupuesto extras/imprevistos
B20: TOTAL ESTIMADO | C20: =SUM(C16:C19)
B23: Objetivos 2-3: Ahorro Individual
B24: Concepto | C24: Ella ($) | D24: Él ($)
B25: Fondo de emergencia personal
B26: Desarrollo profesional
B27: Gustos personales
B28: Otros
B31: Objetivo 4: Compra de Inmueble (Mediano Plazo)
B32: Valor estimado del inmueble
B33: % de entrada requerido
B34: Monto de entrada necesario
B35: Gastos escrituración/notarial
B36: Refacción / Equipamiento
B37: TOTAL A AHORRAR
B40: Objetivo 5: Retiro e Inversiones (Largo Plazo)
B41: Instrumento | C41: Aporte Mensual ($) | D41: Rentabilidad Est. Anual
B42: AFAP voluntario
B43: Fondo de inversión (UI / USD)
B44: Letras de regulación monetaria
B45: Bonos del tesoro
B46: Inversiones en acciones / ETFs
B47: Otros instrumentos

Sheet Seguimiento
B2: SEGUIMIENTO MENSUAL - AÑO 2025
B4: Concepto | C4: Enero | D4: Febrero | E4: Marzo | F4: Abril | G4: Mayo | H4: Junio | I4: Julio | J4: Agosto | K4: Septiembre | L4: Octubre | M4: Noviembre | N4: Diciembre | O4: TOTAL ANUAL
B5: INGRESOS
B6: Ingreso Neto Ella | O6: =SUM(C6:N6)
B7: Ingreso Neto Él | O7: =SUM(C7:N7)
B8: TOTAL INGRESOS | C8: =SUM(C6:C7) | D8: =SUM(D6:D7) | E8: =SUM(E6:E7) | F8: =SUM(F6:F7) | G8: =SUM(G6:G7) | H8: =SUM(H6:H7) | I8: =SUM(I6:I7) | J8: =SUM(J6:J7) | ... O8: =SUM(O6:O7)
B9: GASTOS
B10: Vivienda | O10: =SUM(C10:N10)
B11: Alimentación | O11: =SUM(C11:N11)
B12: Transporte | O12: =SUM(C12:N12)
B13: Salud | O13: =SUM(C13:N13)
B14: Educación | O14: =SUM(C14:N14)
B15: Personal/Ocio | O15: =SUM(C15:N15)
B16: Financiero | O16: =SUM(C16:N16)
B17: TOTAL GASTOS | C17: =SUM(C10:C16) | D17: =SUM(D10:D16) | E17: =SUM(E10:E16) | F17: =SUM(F10:F16) | G17: =SUM(G10:G16) | H17: =SUM(H10:H16) | I17: =SUM(I10:I16) | J17: =SUM(J10:J16) | ... O17: =SUM(O10:O16)
B18: AHORRO POR OBJETIVO
B19: Vacaciones | O19: =SUM(C19:N19)
B20: Ahorro Individual Ella | O20: =SUM(C20:N20)
B21: Ahorro Individual Él | O21: =SUM(C21:N21)
B22: Inmueble | O22: =SUM(C22:N22)
B23: Retiro / Inversiones | O23: =SUM(C23:N23)
B24: TOTAL AHORRO POR OBJETIVO | C24: =SUM(C19:C23) | D24: =SUM(D19:D23) | E24: =SUM(E19:E23) | F24: =SUM(F19:F23) | G24: =SUM(G19:G23) | H24: =SUM(H19:H23) | I24: =SUM(I19:I23) | J24: =SUM(J19:J23) | ... O24: =SUM(O19:O23)
B26: BALANCE MENSUAL | C26: =C8-C17-C24 | D26: =D8-D17-D24 | E26: =E8-E17-E24 | F26: =F8-F17-F24 | G26: =G8-G17-G24 | H26: =H8-H17-H24 | I26: =I8-I17-I24 | J26: =J8-J17-J24 | ... O26: =O8-O17-O24
B27: TASA DE AHORRO | C27: =IF(C8>0,C24/C8,0) | D27: =IF(D8>0,D24/D8,0) | E27: =IF(E8>0,E24/E8,0) | F27: =IF(F8>0,F24/F8,0) | G27: =IF(G8>0,G24/G8,0) | H27: =IF(H8>0,H24/H8,0) | I27: =IF(I8>0,I24/I8,0) | J27: =IF(J8>0,J24/J8,0) | ... O27: =IF(O8>0,O24/O8,0)
B29: AHORRO ACUMULADO | C29: =C24 | D29: =C29+D24 | E29: =D29+E24 | F29: =E29+F24 | G29: =F29+G24 | H29: =G29+H24 | I29: =H29+I24 | J29: =I29+J24 | K29: =J29+K24 | ... O29: =N29+O24

Sheet Inversiones
B2: PORTAFOLIO DE INVERSIONES
B3: Opciones disponibles en Uruguay para residentes médicos
B5: Opciones de Inversión - Uruguay
B6: Instrumento | C6: Riesgo | D6: Liquidez | E6: Moneda | F6: Rent. Est. Anual | G6: Aporte Mensual | H6: Notas
B7: AFAP Voluntaria (República/Unión) | C7: Bajo | D7: Baja | E7: UI/UYU | F7: 3-5% | H7: Deducible de IRPF
B8: Letras de Regulación Monetaria | C8: Muy bajo | D8: Media | E8: UYU | F8: Variable BCU | H8: Plazo 30-360 días
B9: Notas del Tesoro en UI | C9: Bajo | D9: Media | E9: UI | F9: 2-4% real | H9: Protege contra inflación
B10: Bonos Globales Uruguay | C10: Bajo | D10: Media | E10: USD | F10: 4-6% | H10: Renta fija en USD
B11: Depósito a plazo fijo | C11: Muy bajo | D11: Baja | E11: UYU/USD | F11: Variable | H11: Garantía BCU
B12: Fondo de inversión (SURA, etc.) | C12: Medio | D12: Media | E12: USD/UI | F12: 5-8% | H12: Diversificado
B13: Acciones / ETFs (broker int'l) | C13: Alto | D13: Alta | E13: USD | F13: 8-12% | H13: Requiere cuenta exterior
B14: Inmueble (renta) | C14: Medio | D14: Muy baja | E14: UYU/USD | F14: 4-7% | H14: Ingreso pasivo
B15: TOTAL INVERSIÓN MENSUAL | G15: =SUM(G7:G14)
B18: Simulador de Interés Compuesto
B19: Aporte mensual ($)
B20: Tasa anual esperada (%)
B21: Años de inversión
B23: Total Invertido (sin rendimiento) | C23: =C19*C21*12
B24: Valor Futuro (con rendimiento) | C24: =IF(AND(C19>0,C20>0,C21>0),C19*(((1+C20/12)^(C21*12)-1)/(C20/12)),0)
B25: Ganancia por Rendimiento | C25: =C24-C23
B28: Perfil de Riesgo Sugerido para Médicos Residentes
B29: • Prioridad 1: Fondo de emergencia (3-6 meses gastos) en depósito o LRM.
B30: • Prioridad 2: AFAP voluntaria para beneficio fiscal (deducción IRPF).
B31: • Prioridad 3: Notas en UI para ahorro mediano plazo (inmueble).
B32: • Prioridad 4: Diversificar en fondos USD para largo plazo.
B33: • Cuidado: Evitar inversiones ilíquidas mientras están en residencia.
B34: • Tip: Automatizar transferencias el día de cobro.

Sheet Fondo Emergencia
B2: FONDO DE EMERGENCIA
B3: Meta: cubrir 3 a 6 meses de gastos esenciales
B5: Cálculo de Meta
B6: Gastos esenciales mensuales | C6: =Gastos!H43
B7: Meta 3 meses | C7: =C6*3
B8: Meta 6 meses (recomendado) | C8: =C6*6
B9: Ahorrado actualmente
B10: Faltan para meta 3 meses | C10: =MAX(C7-C9,0)
B11: Faltan para meta 6 meses | C11: =MAX(C8-C9,0)
B12: Ahorro mensual para este fondo
B13: Meses para alcanzar meta 3m | C13: =IF(C12>0,C10/C12,"—")
B14: Meses para alcanzar meta 6m | C14: =IF(C12>0,C11/C12,"—")
B17: ¿Dónde guardar el fondo de emergencia?
B18: • Cuenta de ahorro en UYU (acceso inmediato)
B19: • Depósito a plazo 30 días (mejor tasa, algo menos líquido)
B20: • Letras de regulación monetaria corto plazo
B21: • NO en inversiones de riesgo o poco líquidas
B23: IMPORTANTE: Este fondo es intocable salvo emergencia real.
B24: No es para vacaciones, no es para oportunidades de inversión.
